Workbook

Sheet Sheet1
A1: poi_type | B1: maki | D1: maki_original | E1: maki_clean | G1: poi_type | H1: maki_clean
A2: acai shop | B2: restaurant | D2: airport | E2: =TRIM(D2) -> airport | G2: acai shop | H2: shop
A3: accounting | B3: bank | D3: airfield | E3: =TRIM(D3) -> airfield | G3: accounting | H3: bank
A4: adventure sports center | B4: stadium | D4: heliport | E4: =TRIM(D4) -> heliport | G4: adventure sports center | H4: basketball
A5: african restaurant | B5: restaurant | D5: rocket | E5: =TRIM(D5) -> rocket | G5: african restaurant | H5: restaurant
A6: airport | B6: airport | D6: marker | E6: =TRIM(D6) -> marker | G6: airport | H6: airport
A7: amusement park | B7: =TRIM(A7) -> amusement park | D7: mountain | E7: =TRIM(D7) -> mountain | G7: amusement park | H7: amusement-park
A8: apartment building | B8: marker | D8: volcano | E8: =TRIM(D8) -> volcano | G8: apartment building | H8: lodging
A9: apartment complex | B9: marker | D9: waterfall | E9: =TRIM(D9) -> waterfall | G9: apartment complex | H9: lodging
A10: art gallery | B10: art-gallery | D10: alcohol-shop | E10: =TRIM(D10) -> alcohol-shop | G10: art gallery | H10: art-gallery
A11: art studio | B11: art-gallery | D11: american-football | E11: =TRIM(D11) -> american-football | G11: art studio | H11: art-gallery
A12: asian restaurant | B12: restaurant | D12: amusement-park | E12: =TRIM(D12) -> amusement-park | G12: asian restaurant | H12: restaurant-noodle
A13: atm | B13: bank | D13: aquarium | E13: =TRIM(D13) -> aquarium | G13: atm | H13: bank
A14: auditorium | B14: theater | D14: art-gallery | E14: =TRIM(D14) -> art-gallery | G14: auditorium | H14: theatre
A15: auto parts store | B15: shop | D15: attraction | E15: =TRIM(D15) -> attraction | G15: auto parts store | H15: car
A16: bakery | B16: bakery | D16: bakery | E16: =TRIM(D16) -> bakery | G16: bakery | H16: bakery
A17: bank | B17: bank | D17: bank | E17: =TRIM(D17) -> bank | G17: bank | H17: bank
A18: bar | B18: bar | D18: bar | E18: =TRIM(D18) -> bar | G18: bar | H18: bar
A19: bar and grill | B19: restaurant | D19: basketball | E19: =TRIM(D19) -> basketball | G19: bar and grill | H19: restaurant
A20: barber shop | B20: #N/A | D20: beach | E20: =TRIM(D20) -> beach | G20: barber shop | H20: shop
A21: beauty salon | B21: #N/A | D21: beer | E21: =TRIM(D21) -> beer | G21: beauty salon | H21: shop
A22: bed and breakfast | B22: fast-food | D22: bicycle | E22: =TRIM(D22) -> bicycle | G22: bed and breakfast | H22: lodging
A23: bicycle store | B23: bicycle | D23: bowling-alley | E23: =TRIM(D23) -> bowling-alley | G23: bicycle store | H23: bicycle
A24: body art service | B24: art-gallery | D24: bridge | E24: =TRIM(D24) -> bridge | G24: body art service | H24: shop
A25: book store | B25: #N/A | D25: cafe | E25: =TRIM(D25) -> cafe | G25: book store | H25: shop
A26: botanical garden | B26: #N/A | D26: campsite | E26: =TRIM(D26) -> campsite | G26: botanical garden | H26: garden
A27: buffet restaurant | B27: #N/A | D27: car | E27: =TRIM(D27) -> car | G27: buffet restaurant | H27: restaurant
A28: building | B28: #N/A | D28: car-rental | E28: =TRIM(D28) -> car-rental | G28: building | H28: marker
A29: bus station | B29: #N/A | D29: car-repair | E29: =TRIM(D29) -> car-repair | G29: bus station | H29: bus
A30: bus stop | B30: #N/A | D30: casino | E30: =TRIM(D30) -> casino | G30: bus stop | H30: bus
A31: butcher shop | B31: #N/A | D31: castle | E31: =TRIM(D31) -> castle | G31: butcher shop | H31: shop
A32: cafeteria | B32: #N/A | D32: cemetery | E32: =TRIM(D32) -> cemetery | G32: cafeteria | H32: cafe
A33: candy store | B33: #N/A | D33: charging-station | E33: =TRIM(D33) -> charging-station | G33: candy store | H33: confectionery
A34: car dealer | B34: #N/A | D34: cinema | E34: =TRIM(D34) -> cinema | G34: car dealer | H34: car
A35: car rental | B35: #N/A | D35: clothing-store | E35: =TRIM(D35) -> clothing-store | G35: car rental | H35: car-rental
A36: car repair | B36: #N/A | D36: college | E36: =TRIM(D36) -> college | G36: car repair | H36: car-repair
... A39: cell phone store | B39: #N/A | D39: convenience | E39: =TRIM(D39) -> convenience | G39: cell phone store | H39: mobile-phone
A40: cemetery | B40: cemetery | D40: dentist | E40: =TRIM(D40) -> dentist | G40: cemetery | H40: cemetery
A41: child care agency | B41: #N/A | D41: doctor | E41: =TRIM(D41) -> doctor | G41: child care agency | H41: school
A42: childrens camp | B42: #N/A | D42: dog-park | E42: =TRIM(D42) -> dog-park | G42: childrens camp | H42: campsite
...

Sheet Sheet3
A1: maki | B1: class | I1: category | J1: color
A2: airport | B2: motorist | I2: motorist | J2: 78553a
A3: airfield | B3: motorist | I3: landmark | J3: 78553a
A4: heliport | B4: motorist | I4: general | J4: 78553a
A5: rocket | B5: landmark | I5: park_like | J5: 78553a
A6: marker | B6: general | I6: food_and_drink_stores | J6: b64f1b
A7: mountain | B7: landmark | I7: sport_and_leisure | J7: 78553a
A8: volcano | B8: landmark | I8: arts_and_entertainment | J8: 78553a
A9: waterfall | B9: park_like | I9: visitor_amenities | J9: 78553a
A10: alcohol-shop | B10: food_and_drink_stores | I10: commercial_services | J10: 78553a
A11: american-football | B11: sport_and_leisure | I11: food_and_drink | J11: b64f1b
A12: amusement-park | B12: sport_and_leisure | I12: historic | J12: 78553a
... A20: beach | B20: park_like | I20: religion | J20: 78553a
A21: beer | B21: food_and_drink
A22: bicycle | B22: motorist
A23: bowling-alley | B23: sport_and_leisure
A24: bridge | B24: landmark
A25: cafe | B25: food_and_drink
A26: campsite | B26: park_like
A27: car | B27: motorist
A28: car-rental | B28: motorist
A29: car-repair | B29: motorist
A30: casino | B30: arts_and_entertainment
A31: castle | B31: historic
A32: cemetery | B32: park_like
... A116: entrance | B116: general

Sheet maki
A1: poi_type | B1: maki | C1: osm_icon | D1: class
A2: acai shop | B2: shop | C2: shop | D2: =INDEX(Sheet3!B:B, MATCH(maki!B2,Sheet3!A:A,0)) -> store_like
A3: accounting | B3: bank | C3: bank | D3: =INDEX(Sheet3!B:B, MATCH(maki!B3,Sheet3!A:A,0)) -> commercial_services
A4: adventure sports center | B4: playground | C4: playground | D4: =INDEX(Sheet3!B:B, MATCH(maki!B4,Sheet3!A:A,0)) -> park_like
A5: african restaurant | B5: restaurant | C5: restaurant | D5: =INDEX(Sheet3!B:B, MATCH(maki!B5,Sheet3!A:A,0)) -> food_and_drink
A6: airport | B6: airport | C6: airport | D6: =INDEX(Sheet3!B:B, MATCH(maki!B6,Sheet3!A:A,0)) -> motorist
A7: amusement park | B7: amusement-park | C7: amusement_park | D7: =INDEX(Sheet3!B:B, MATCH(maki!B7,Sheet3!A:A,0)) -> sport_and_leisure
A8: apartment building | B8: lodging | C8: lodging | D8: =INDEX(Sheet3!B:B, MATCH(maki!B8,Sheet3!A:A,0)) -> lodging
A9: apartment complex | B9: lodging | C9: lodging | D9: =INDEX(Sheet3!B:B, MATCH(maki!B9,Sheet3!A:A,0)) -> lodging
A10: art gallery | B10: art-gallery | C10: art_gallery | D10: =INDEX(Sheet3!B:B, MATCH(maki!B10,Sheet3!A:A,0)) -> arts_and_entertainment
A11: art studio | B11: art-gallery | C11: art_gallery | D11: =INDEX(Sheet3!B:B, MATCH(maki!B11,Sheet3!A:A,0)) -> arts_and_entertainment
A12: asian restaurant | B12: restaurant-noodle | C12: restaurant | D12: =INDEX(Sheet3!B:B, MATCH(maki!B12,Sheet3!A:A,0)) -> food_and_drink
A13: atm | B13: bank | C13: bank | D13: =INDEX(Sheet3!B:B, MATCH(maki!B13,Sheet3!A:A,0)) -> commercial_services
... A198: zoo | B198: zoo | C198: zoo | D198: =INDEX(Sheet3!B:B, MATCH(maki!B198,Sheet3!A:A,0)) -> park_like

Sheet osm
A1: poi_type | B1: osm_sprite | C1: class
A2: acai shop | B2: shop | C2: =INDEX(maki!D:D,MATCH(osm!B2,maki!C:C,0)) -> store_like
A3: accounting | B3: town_hall | C3: =INDEX(maki!D:D,MATCH(osm!B3,maki!C:C,0)) -> building
A4: adventure sports center | B4: park | C4: =INDEX(maki!D:D,MATCH(osm!B4,maki!C:C,0)) -> park_like
A5: african restaurant | B5: restaurant | C5: =INDEX(maki!D:D,MATCH(osm!B5,maki!C:C,0)) -> food_and_drink
A6: airport | B6: airport | C6: =INDEX(maki!D:D,MATCH(osm!B6,maki!C:C,0)) -> motorist
A7: amusement park | B7: amusement_park | C7: =INDEX(maki!D:D,MATCH(osm!B7,maki!C:C,0)) -> sport_and_leisure
A8: apartment building | B8: building | C8: =INDEX(maki!D:D,MATCH(osm!B8,maki!C:C,0)) -> #N/A
A9: apartment complex | B9: housing_complex | C9: =INDEX(maki!D:D,MATCH(osm!B9,maki!C:C,0)) -> #N/A
A10: art gallery | B10: art_gallery | C10: =INDEX(maki!D:D,MATCH(osm!B10,maki!C:C,0)) -> arts_and_entertainment
A11: art studio | B11: art_gallery | C11: =INDEX(maki!D:D,MATCH(osm!B11,maki!C:C,0)) -> arts_and_entertainment
A12: asian restaurant | B12: restaurant | C12: =INDEX(maki!D:D,MATCH(osm!B12,maki!C:C,0)) -> food_and_drink
A13: atm | B13: bank | C13: =INDEX(maki!D:D,MATCH(osm!B13,maki!C:C,0)) -> commercial_services
... A198: zoo | B198: zoo | C198: =INDEX(maki!D:D,MATCH(osm!B198,maki!C:C,0)) -> park_like

Sheet source
B1: osm | D1: maki | F1: category
B2: airfield | D2: aerialway | F2: motorist
B3: airport | D3: airfield | F3: landmark
B4: alcohol_shop | D4: airport | F4: general
B5: amusement_park | D5: alcohol-shop | F5: park_like
B6: aquarium | D6: american-football | F6: food_and_drink_stores
B7: art_gallery | D7: amusement-park | F7: sport_and_leisure
B8: attraction | D8: animal-shelter | F8: arts_and_entertainment
B9: bakery | D9: aquarium | F9: visitor_amenities
B10: bank | D10: arrow | F10: commercial_services
B11: bar | D11: art-gallery | F11: food_and_drink
B12: beer | D12: attraction | F12: historic
... B20: cemetery | D20: bbq | F20: religion
B21: cinema | D21: beach
B22: circle | D22: beer
B23: circle_stroked | D23: bicycle-share
B24: clothing_store | D24: bicycle
B25: college | D25: blood-bank
B26: dentist | D26: bowling-alley
B27: doctor | D27: bridge
B28: dog_park | D28: building-alt1
B29: drinking_water | D29: building
B30: embassy | D30: bus
B31: entrance | D31: cafe
B32: fast_food | D32: campsite
... B82: zoo | D82: garden-centre
D83: garden
D84: gate
D85: gift
D86: globe
D87: golf
D88: grocery
D89: hairdresser
D90: harbor
D91: hardware
D92: heart
D93: heliport
D94: highway-rest-area
... D216: zoo
